Workbook

Sheet Табло
A2: BDS напредък и следващи действия
A4: Към | B4: =Допускания!D7 -> 46282 | F4: =HYPERLINK("BDS_Plan.docx","Отвори BDS Plan") -> Отвори BDS Plan
A6: Всеки ден | B6: Отмятай задачите в Word. Помощникът обновява това табло автоматично.
A7: В петък | B7: Попълни числата в Седмици. Пълнотата се проверява автоматично.
A8: Месечно | B8: Попълни Месеци и приключи отчетения период.
A10: Период | B10: Изпълнение | C10: Готови | D10: Общо | F10: Период | G10: Готови | H10: Остават
A11: 14 дни | B11: =C11/D11 -> 0 | C11: =SUMIFS(Задачи!$I$7:$I$38,Задачи!$B$7:$B$38,A11) -> 0 | D11: =COUNTIFS(Задачи!$B$7:$B$38,A11) -> 17 | F11: =A11 -> 14 дни | G11: =C11 -> 0 | H11: =D11-C11 -> 17
A12: 30 дни | B12: =C12/D12 -> 0 | C12: =SUMIFS(Задачи!$I$7:$I$38,Задачи!$B$7:$B$38,A12) -> 0 | D12: =COUNTIFS(Задачи!$B$7:$B$38,A12) -> 6 | F12: =A12 -> 30 дни | G12: =C12 -> 0 | H12: =D12-C12 -> 6
A13: 90 дни | B13: =C13/D13 -> 0 | C13: =SUMIFS(Задачи!$I$7:$I$38,Задачи!$B$7:$B$38,A13) -> 0 | D13: =COUNTIFS(Задачи!$B$7:$B$38,A13) -> 6 | F13: =A13 -> 90 дни | G13: =C13 -> 0 | H13: =D13-C13 -> 6
A14: След условия | B14: =C14/D14 -> 0 | C14: =SUMIFS(Задачи!$I$7:$I$38,Задачи!$B$7:$B$38,A14) -> 0 | D14: =COUNTIFS(Задачи!$B$7:$B$38,A14) -> 3 | F14: =A14 -> След условия | G14: =C14 -> 0 | H14: =D14-C14 -> 3
A16: Заявено изпълнение | B16: =SUM(Задачи!I7:I38)/32 -> 0
A17: Просрочени | B17: =COUNTIFS(Задачи!$I$7:$I$38,0,Задачи!$F$7:$F$38,"<"&Допускания!$D$7,Задачи!$E$7:$E$38,"<>Отложено") -> 0
A18: Блокирани | B18: =COUNTIFS(Задачи!$E$7:$E$38,"Блокирано") -> 0
A19: Провери условията | B19: =COUNTIFS(Задачи!$I$7:$I$38,1,Задачи!$R$7:$R$38,0) -> 0
A21: Текущ етап | B21: =IF(B11<1,"Основи и първи платени сделки",IF(B12<1,"Повторяем delivery и recurring пилоти",IF(B13<1,"Делегиране и доказване на модела","Провери финансовата устойчивост"))) -> Основи и първи платени сделки
A29: Ред | B29: Следваща задача | C29: ID | D29: Срок
A30: 1 | B30: =IF(COUNTIFS(Задачи!$S$7:$S$38,A30)=0,"Няма готова за старт задача",INDEX(Задачи!$C$7:$C$38,MATCH(A30,Задачи!$S$7:$S$38,0))) -> Реши видимостта на repository | C30: =IF(COUNTIFS(Задачи!$S$7:$S$38,A30)=0,"",INDEX(Задачи!$A$7:$A$38,MATCH(A30,Задачи!$S$7:$S$38,0))) -> T02 | D30: =IF(C30="","",INDEX(Задачи!$F$7:$F$38,MATCH(A30,Задачи!$S$7:$S$38,0))) -> 46286 | F30: Започни от | H30: =HYPERLINK("#'Задачи'!A6","Задачи") -> Задачи
A31: 2 | B31: =IF(COUNTIFS(Задачи!$S$7:$S$38,A31)=0,"Няма готова за старт задача",INDEX(Задачи!$C$7:$C$38,MATCH(A31,Задачи!$S$7:$S$38,0))) -> Започни отчитане на часове и разход | C31: =IF(COUNTIFS(Задачи!$S$7:$S$38,A31)=0,"",INDEX(Задачи!$A$7:$A$38,MATCH(A31,Задачи!$S$7:$S$38,0))) -> T04 | D31: =IF(C31="","",INDEX(Задачи!$F$7:$F$38,MATCH(A31,Задачи!$S$7:$S$38,0))) -> 46287 | F31: Промени старт | H31: =HYPERLINK("#'Допускания'!C5","Допускания") -> Допускания
A32: 3 | B32: =IF(COUNTIFS(Задачи!$S$7:$S$38,A32)=0,"Няма готова за старт задача",INDEX(Задачи!$C$7:$C$38,MATCH(A32,Задачи!$S$7:$S$38,0))) -> Въведи реалното начално състояние | C32: =IF(COUNTIFS(Задачи!$S$7:$S$38,A32)=0,"",INDEX(Задачи!$A$7:$A$38,MATCH(A32,Задачи!$S$7:$S$38,0))) -> T01 | D32: =IF(C32="","",INDEX(Задачи!$F$7:$F$38,MATCH(A32,Задачи!$S$7:$S$38,0))) -> 46286 | F32: Кого да търся | H32: =HYPERLINK("#'Лийдове'!A6","Лийдове") -> Лийдове
A35: Показател | B35: Реално | C35: Цел | D35: Прогрес | F35: Последен затворен месец | J35: =IF(COUNTIFS(Месеци!$Q$7:$Q$42,"Да",Месеци!$A$7:$A$42,"<"&DATE(YEAR(Допускания!$D$7),MONTH(Допускания!$D$7),1))=0,"",SUMPRODUCT((Месеци!$Q$7:$Q$42="Да")*(Месеци!$A$7:$A$42<DATE(YEAR(Допускания!$D$7),MONTH(Допускания!$D$7),1))*(Месеци!$A$7:$A$42=_xlfn.MAXIFS(Месеци!$A$7:$A$42,Месеци!$Q$7:$Q$42,"Да",Месеци!$A$7:$A$42,"<"&DATE(YEAR(Допускания!$D$7),MONTH(Допускания!$D$7),1)))*(ROW(Месеци!$A$7:$A$42)-6)))
A36: Приход | B36: =IF($J$35="","Няма данни",IF(NOT(ISNUMBER(INDEX(Месеци!$D$7:$D$42,$J$35))),"Няма данни",INDEX(Месеци!$D$7:$D$42,$J$35))) -> Няма данни | C36: =Допускания!D8 -> 30000 | D36: =IF(ISNUMBER(B36),B36/C36,"") | J36: =IF(J35="","Няма данни",INDEX(Месеци!$A$7:$A$42,J35)) -> Няма данни
A37: MRR | B37: =IF($J$35="","Няма данни",IF(NOT(ISNUMBER(INDEX(Месеци!$E$7:$E$42,$J$35))),"Няма данни",INDEX(Месеци!$E$7:$E$42,$J$35))) -> Няма данни | C37: =Допускания!D9 -> 15000 | D37: =IF(ISNUMBER(B37),B37/C37,"")
A38: Опер. марж | B38: =IF($J$35="","Няма данни",IF(NOT(ISNUMBER(INDEX(Месеци!$I$7:$I$42,$J$35))),"Няма данни",INDEX(Месеци!$I$7:$I$42,$J$35))) -> Няма данни | C38: =Допускания!D10 -> 0.25 | D38: =IF(ISNUMBER(B38),B38/C38,"") | F38: Устойчиви 30k | J38: =IF(ISNUMBER(B39),IF(B39>=Допускания!D12,"Потвърдено","Още не"),B39) -> Няма данни
A39: Месеци 30k | B39: =IF($J$35="","Няма данни",IF(NOT(ISNUMBER(INDEX(Месеци!$R$7:$R$42,$J$35))),"Непълни данни",INDEX(Месеци!$S$7:$S$42,$J$35))) -> Няма данни | C39: =Допускания!D12 -> 3 | D39: =IF(ISNUMBER(B39),B39/C39,"") | F39: Устойчиви 50k | J39: =IF(ISNUMBER(B40),IF(B40>=Допускания!D12,"Потвърдено","Още не"),B40) -> Няма данни
A40: Месеци 50k | B40: =IF($J$35="","Няма данни",IF(NOT(ISNUMBER(INDEX(Месеци!$T$7:$T$42,$J$35))),"Непълни данни",INDEX(Месеци!$U$7:$U$42,$J$35))) -> Няма данни | C40: =Допускания!D12 -> 3 | D40: =IF(ISNUMBER(B40),B40/C40,"")
F41: Задачите и приходът са отделни показатели.
A43: Метрика | B43: Последни 4 седмици | C43: План на седмица
A44: Prospects | B44: =IF(COUNTIFS(Седмици!$N$7:$N$162,"Да",Седмици!$A$7:$A$162,">="&Допускания!$D$7-28,Седмици!$A$7:$A$162,"<="&Допускания!$D$7)=0,"Няма данни",SUMIFS(Седмици!$B$7:$B$162,Седмици!$N$7:$N$162,"Да",Седмици!$A$7:$A$162,">="&Допускания!$D$7-28,Седмици!$A$7:$A$162,"<="&Допускания!$D$7)) -> Няма данни | C44: =ROUNDUP(INDEX(Модел!$D$66:$H$66,1,MATCH(Допускания!$D$8,Модел!$D$7:$H$7,0))/Допускания!$D$50,0) -> 157 | F44: Избран прогнозен модел | J44: =Допускания!F5 -> PLANNED Growth
A45: Call attempts | B45: =IF(COUNTIFS(Седмици!$N$7:$N$162,"Да",Седмици!$A$7:$A$162,">="&Допускания!$D$7-28,Седмици!$A$7:$A$162,"<="&Допускания!$D$7)=0,"Няма данни",SUMIFS(Седмици!$C$7:$C$162,Седмици!$N$7:$N$162,"Да",Седмици!$A$7:$A$162,">="&Допускания!$D$7-28,Седмици!$A$7:$A$162,"<="&Допускания!$D$7)) -> Няма данни | C45: =ROUNDUP(INDEX(Модел!$D$67:$H$67,1,MATCH(Допускания!$D$8,Модел!$D$7:$H$7,0))/Допускания!$D$50,0) -> 314
A46: Held meetings | B46: =IF(COUNTIFS(Седмици!$N$7:$N$162,"Да",Седмици!$A$7:$A$162,">="&Допускания!$D$7-28,Седмици!$A$7:$A$162,"<="&Допускания!$D$7)=0,"Няма данни",SUMIFS(Седмици!$F$7:$F$162,Седмици!$N$7:$N$162,"Да",Седмици!$A$7:$A$162,">="&Допускания!$D$7-28,Седмици!$A$7:$A$162,"<="&Допускания!$D$7)) -> Няма данни | C46: =ROUNDUP(INDEX(Модел!$D$63:$H$63,1,MATCH(Допускания!$D$8,Модел!$D$7:$H$7,0))/Допускания!$D$50,0) -> 13 | F46: =HYPERLINK("#'Модел'!C7","Виж финансовите сценарии") -> Виж финансовите сценарии
A47: Proposals | B47: =IF(COUNTIFS(Седмици!$N$7:$N$162,"Да",Седмици!$A$7:$A$162,">="&Допускания!$D$7-28,Седмици!$A$7:$A$162,"<="&Допускания!$D$7)=0,"Няма данни",SUMIFS(Седмици!$G$7:$G$162,Седмици!$N$7:$N$162,"Да",Седмици!$A$7:$A$162,">="&Допускания!$D$7-28,Седмици!$A$7:$A$162,"<="&Допускания!$D$7)) -> Няма данни | C47: =ROUNDUP(INDEX(Модел!$D$62:$H$62,1,MATCH(Допускания!$D$8,Модел!$D$7:$H$7,0))/Допускания!$D$50,0) -> 10
A50: Процентът отчита отметките ти. Реалните приходи, MRR и устойчивост се доказват отделно.
A51: Автоматично обновяване след 1_SETUP.cmd. Дръж двата файла и помощника в тази папка.
A53: Последна връзка | B53: Още не е активирана. Стартирай 1_SETUP.cmd.

Sheet Задачи
A2: План за изпълнение и доказателства
A4: Word управлява Готово и Дата готово. Отметката е самооценка; бележките са по избор. Не преименувай ID.
A6: ID | B6: Период | C6: Задача | D6: Отговорник | E6: Статус | F6: Срок | G6: Дата готово | H6: Бележка или доказателство | I6: Отметнато | J6: Какво остава | K6: Приоритет | L6: Зависи от 1 | M6: Зависи от 2 | N6: Impact | O6: Urgency | P6: Effort | Q6: Dependency | R6: Готови условия | S6: Ред за действие | T6: Word | U6: Критерий за готово
A7: T01 | B7: 14 дни | C7: Въведи реалното начално състояние | D7: Преслав | E7: Не е започнато | F7: =Допускания!$D$6+0 -> 46286 | I7: =IF(E7="Готово",1,0) -> 0 | J7: =IF(I7=1,IF(R7=1,"Готово по отметка","Отметнато; провери условията"),IF(E7="Отложено","Отложено",IF(R7=0,"Чака зависимост",IF(E7="Блокирано","Премахни блокирането",IF(F7<Допускания!$D$7,"Просрочено","За изпълнение"))))) -> За изпълнение | K7: =N7*O7*Q7/P7 -> 25 | N7: 5 | O7: 5 | P7: 2 | Q7: =IF(COUNTIFS($L$7:$L$38,A7)+COUNTIFS($M$7:$M$38,A7)>0,2,1) -> 2 | R7: =IF(AND(OR(L7="",COUNTIFS($A$7:$A$38,L7,$I$7:$I$38,1)=1),OR(M7="",COUNTIFS($A$7:$A$38,M7,$I$7:$I$38,1)=1)),1,0) -> 1 | S7: =IF(AND(I7=0,R7=1,E7<>"Блокирано",E7<>"Отложено"),COUNTIFS($R$7:$R$38,1,$I$7:$I$38,0,$E$7:$E$38,"<>Блокирано",$E$7:$E$38,"<>Отложено",$K$7:$K$38,">"&K7)+COUNTIFS($R$7:R7,1,$I$7:I7,0,$E$7:E7,"<>Блокирано",$E$7:E7,"<>Отложено",$K$7:K7,K7),"") -> 3 | T7: =HYPERLINK("BDS_Plan.docx#T01","T01 в Word") -> T01 в Word | U7: Последният приключен месец има приходи, MRR, разходи, плащания и активни клиенти; списък с платения backlog.
A8: T02 | B8: 14 дни | C8: Реши видимостта на repository | D8: Преслав | E8: Не е започнато | F8: =Допускания!$D$6+0 -> 46286 | I8: =IF(E8="Готово",1,0) -> 0 | J8: =IF(I8=1,IF(R8=1,"Готово по отметка","Отметнато; провери условията"),IF(E8="Отложено","Отложено",IF(R8=0,"Чака зависимост",IF(E8="Блокирано","Премахни блокирането",IF(F8<Допускания!$D$7,"Просрочено","За изпълнение"))))) -> За изпълнение | K8: =N8*O8*Q8/P8 -> 50 | N8: 5 | O8: 5 | P8: 1 | Q8: =IF(COUNTIFS($L$7:$L$38,A8)+COUNTIFS($M$7:$M$38,A8)>0,2,1) -> 2 | R8: =IF(AND(OR(L8="",COUNTIFS($A$7:$A$38,L8,$I$7:$I$38,1)=1),OR(M8="",COUNTIFS($A$7:$A$38,M8,$I$7:$I$38,1)=1)),1,0) -> 1 | S8: =IF(AND(I8=0,R8=1,E8<>"Блокирано",E8<>"Отложено"),COUNTIFS($R$7:$R$38,1,$I$7:$I$38,0,$E$7:$E$38,"<>Блокирано",$E$7:$E$38,"<>Отложено",$K$7:$K$38,">"&K8)+COUNTIFS($R$7:R8,1,$I$7:I8,0,$E$7:E8,"<>Блокирано",$E$7:E8,"<>Отложено",$K$7:K8,K8),"") -> 1 | T8: =HYPERLINK("BDS_Plan.docx#T02","T02 в Word") -> T02 в Word | U8: Документирано решение за public/private; прегледани вътрешни данни и публичният build.
A9: T03 | B9: 14 дни | C9: Подреди съществуващите възможности | D9: Преслав | E9: Не е започнато | F9: =Допускания!$D$6+1 -> 46287 | I9: =IF(E9="Готово",1,0) -> 0 | J9: =IF(I9=1,IF(R9=1,"Готово по отметка","Отметнато; провери условията"),IF(E9="Отложено","Отложено",IF(R9=0,"Чака зависимост",IF(E9="Блокирано","Премахни блокирането",IF(F9<Допускания!$D$7,"Просрочено","За изпълнение"))))) -> Чака зависимост | K9: =N9*O9*Q9/P9 -> 50 | L9: T01 | N9: 5 | O9: 5 | P9: 1 | Q9: =IF(COUNTIFS($L$7:$L$38,A9)+COUNTIFS($M$7:$M$38,A9)>0,2,1) -> 2 | R9: =IF(AND(OR(L9="",COUNTIFS($A$7:$A$38,L9,$I$7:$I$38,1)=1),OR(M9="",COUNTIFS($A$7:$A$38,M9,$I$7:$I$38,1)=1)),1,0) -> 0 | S9: =IF(AND(I9=0,R9=1,E9<>"Блокирано",E9<>"Отложено"),COUNTIFS($R$7:$R$38,1,$I$7:$I$38,0,$E$7:$E$38,"<>Блокирано",$E$7:$E$38,"<>Отложено",$K$7:$K$38,">"&K9)+COUNTIFS($R$7:R9,1,$I$7:I9,0,$E$7:E9,"<>Блокирано",$E$7:E9,"<>Отложено",$K$7:K9,K9),"") | T9: =HYPERLINK("BDS_Plan.docx#T03","T03 в Word") -> T03 в Word | U9: Всяка активна сделка има собственик, следващо действие и дата.
A10: T04 | B10: 14 дни | C10: Започни отчитане на часове и разход | D10: Преслав | E10: Не е започнато | F10: =Допускания!$D$6+1 -> 46287 | I10: =IF(E10="Готово",1,0) -> 0 | J10: =IF(I10=1,IF(R10=1,"Готово по отметка","Отметнато; провери условията"),IF(E10="Отложено","Отложено",IF(R10=0,"Чака зависимост",IF(E10="Блокирано","Премахни блокирането",IF(F10<Допускания!$D$7,"Просрочено","За изпълнение"))))) -> За изпълнение | K10: =N10*O10*Q10/P10 -> 40 | N10: 5 | O10: 4 | P10: 1 | Q10: =IF(COUNTIFS($L$7:$L$38,A10)+COUNTIFS($M$7:$M$38,A10)>0,2,1) -> 2 | R10: =IF(AND(OR(L10="",COUNTIFS($A$7:$A$38,L10,$I$7:$I$38,1)=1),OR(M10="",COUNTIFS($A$7:$A$38,M10,$I$7:$I$38,1)=1)),1,0) -> 1 | S10: =IF(AND(I10=0,R10=1,E10<>"Блокирано",E10<>"Отложено"),COUNTIFS($R$7:$R$38,1,$I$7:$I$38,0,$E$7:$E$38,"<>Блокирано",$E$7:$E$38,"<>Отложено",$K$7:$K$38,">"&K10)+COUNTIFS($R$7:R10,1,$I$7:I10,0,$E$7:E10,"<>Блокирано",$E$7:E10,"<>Отложено",$K$7:K10,K10),"") -> 2 | T10: =HYPERLINK("BDS_Plan.docx#T04","T04 в Word") -> T04 в Word | U10: Всеки активен проект и абонамент има estimate, actual hours и отговорник.
A11: T05 | B11: 14 дни | C11: Избери един ICP и водещ продукт | D11: Преслав | E11: Не е започнато | F11: =Допускания!$D$6+2 -> 46288 | I11: =IF(E11="Готово",1,0) -> 0 | J11: =IF(I11=1,IF(R11=1,"Готово по отметка","Отметнато; провери условията"),IF(E11="Отложено","Отложено",IF(R11=0,"Чака зависимост",IF(E11="Блокирано","Премахни блокирането",IF(F11<Допускания!$D$7,"Просрочено","За изпълнение"))))) -> Чака зависимост | K11: =N11*O11*Q11/P11 -> 25 | L11: T01 | M11: T03 | N11: 5 | O11: 5 | P11: 2 | Q11: =IF(COUNTIFS($L$7:$L$38,A11)+COUNTIFS($M$7:$M$38,A11)>0,2,1) -> 2 | R11: =IF(AND(OR(L11="",COUNTIFS($A$7:$A$38,L11,$I$7:$I$38,1)=1),OR(M11="",COUNTIFS($A$7:$A$38,M11,$I$7:$I$38,1)=1)),1,0) -> 0 | S11: =IF(AND(I11=0,R11=1,E11<>"Блокирано",E11<>"Отложено"),COUNTIFS($R$7:$R$38,1,$I$7:$I$38,0,$E$7:$E$38,"<>Блокирано",$E$7:$E$38,"<>Отложено",$K$7:$K$38,">"&K11)+COUNTIFS($R$7:R11,1,$I$7:I11,0,$E$7:E11,"<>Блокирано",$E$7:E11,"<>Отложено",$K$7:K11,K11),"") | T11: =HYPERLINK("BDS_Plan.docx#T05","T05 в Word") -> T05 в Word | U11: Една целева група, един измерим проблем и една повторяема оферта; изборът е подкрепен с разговори.
A12: T06 | B12: 14 дни | C12: Фиксирай обхват и минимален марж | D12: Преслав | E12: Не е започнато | F12: =Допускания!$D$6+3 -> 46289 | I12: =IF(E12="Готово",1,0) -> 0 | J12: =IF(I12=1,IF(R12=1,"Готово по отметка","Отметнато; провери условията"),IF(E12="Отложено","Отложено",IF(R12=0,"Чака зависимост",IF(E12="Блокирано","Премахни блокирането",IF(F12<Допускания!$D$7,"Просрочено","За изпълнение"))))) -> Чака зависимост | K12: =N12*O12*Q12/P12 -> 25 | L12: T04 | M12: T05 | N12: 5 | O12: 5 | P12: 2 | Q12: =IF(COUNTIFS($L$7:$L$38,A12)+COUNTIFS($M$7:$M$38,A12)>0,2,1) -> 2 | R12: =IF(AND(OR(L12="",COUNTIFS($A$7:$A$38,L12,$I$7:$I$38,1)=1),OR(M12="",COUNTIFS($A$7:$A$38,M12,$I$7:$I$38,1)=1)),1,0) -> 0 | S12: =IF(AND(I12=0,R12=1,E12<>"Блокирано",E12<>"Отложено"),COUNTIFS($R$7:$R$38,1,$I$7:$I$38,0,$E$7:$E$38,"<>Блокирано",$E$7:$E$38,"<>Отложено",$K$7:$K$38,">"&K12)+COUNTIFS($R$7:R12,1,$I$7:I12,0,$E$7:E12,"<>Блокирано",$E$7:E12,"<>Отложено",$K$7:K12,K12),"") | T12: =HYPERLINK("BDS_Plan.docx#T06","T06 в Word") -> T06 в Word | U12: Офертата има включено/изключено, лимити, приемане, срок след материали и калкулация.
A13: T07 | B13: 14 дни | C13: Обедини входящите лийдове | D13: Технически отговорник | E13: Не е започнато | F13: =Допускания!$D$6+4 -> 46290 | I13: =IF(E13="Готово",1,0) -> 0 | J13: =IF(I13=1,IF(R13=1,"Готово по отметка","Отметнато; провери условията"),IF(E13="Отложено","Отложено",IF(R13=0,"Чака зависимост",IF(E13="Блокирано","Премахни блокирането",IF(F13<Допускания!$D$7,"Просрочено","За изпълнение"))))) -> Чака зависимост | K13: =N13*O13*Q13/P13 -> 16.666667 | L13: T02 | N13: 5 | O13: 5 | P13: 3 | Q13: =IF(COUNTIFS($L$7:$L$38,A13)+COUNTIFS($M$7:$M$38,A13)>0,2,1) -> 2 | R13: =IF(AND(OR(L13="",COUNTIFS($A$7:$A$38,L13,$I$7:$I$38,1)=1),OR(M13="",COUNTIFS($A$7:$A$38,M13,$I$7:$I$38,1)=1)),1,0) -> 0 | S13: =IF(AND(I13=0,R13=1,E13<>"Блокирано",E13<>"Отложено"),COUNTIFS($R$7:$R$38,1,$I$7:$I$38,0,$E$7:$E$38,"<>Блокирано",$E$7:$E$38,"<>Отложено",$K$7:$K$38,">"&K13)+COUNTIFS($R$7:R13,1,$I$7:I13,0,$E$7:E13,"<>Блокирано",$E$7:E13,"<>Отложено",$K$7:K13,K13),"") | T13: =HYPERLINK("BDS_Plan.docx#T07","T07 в Word") -> T07 в Word | U13: Двете форми създават един проследим LeadID; има лог на неуспехите и проверка за дублиране.
A14: T08 | B14: 14 дни | C14: Провери tracking и Ads акаунтите | D14: Преслав | E14: Не е започнато | F14: =Допускания!$D$6+5 -> 46291 | I14: =IF(E14="Готово",1,0) -> 0 | J14: =IF(I14=1,IF(R14=1,"Готово по отметка","Отметнато; провери условията"),IF(E14="Отложено","Отложено",IF(R14=0,"Чака зависимост",IF(E14="Блокирано","Премахни блокирането",IF(F14<Допускания!$D$7,"Просрочено","За изпълнение"))))) -> Чака зависимост | K14: =N14*O14*Q14/P14 -> 10 | L14: T07 | N14: 4 | O14: 5 | P14: 2 | Q14: =IF(COUNTIFS($L$7:$L$38,A14)+COUNTIFS($M$7:$M$38,A14)>0,2,1) -> 1 | R14: =IF(AND(OR(L14="",COUNTIFS($A$7:$A$38,L14,$I$7:$I$38,1)=1),OR(M14="",COUNTIFS($A$7:$A$38,M14,$I$7:$I$38,1)=1)),1,0) -> 0 | S14: =IF(AND(I14=0,R14=1,E14<>"Блокирано",E14<>"Отложено"),COUNTIFS($R$7:$R$38,1,$I$7:$I$38,0,$E$7:$E$38,"<>Блокирано",$E$7:$E$38,"<>Отложено",$K$7:$K$38,">"&K14)+COUNTIFS($R$7:R14,1,$I$7:I14,0,$E$7:E14,"<>Блокирано",$E$7:E14,"<>Отложено",$K$7:K14,K14),"") | T14: =HYPERLINK("BDS_Plan.docx#T08","T08 в Word") -> T08 в Word | U14: Тестов lead се вижда еднократно в CRM и analytics; потвърдени правилни Ads IDs и consent.
A15: T09 | B15: 14 дни | C15: Добави задължителни CRM действия | D15: Sales Ops | E15: Не е започнато | F15: =Допускания!$D$6+4 -> 46290 | I15: =IF(E15="Готово",1,0) -> 0 | J15: =IF(I15=1,IF(R15=1,"Готово по отметка","Отметнато; провери условията"),IF(E15="Отложено","Отложено",IF(R15=0,"Чака зависимост",IF(E15="Блокирано","Премахни блокирането",IF(F15<Допускания!$D$7,"Просрочено","За изпълнение"))))) -> Чака зависимост | K15: =N15*O15*Q15/P15 -> 25 | L15: T03 | N15: 5 | O15: 5 | P15: 2 | Q15: =IF(COUNTIFS($L$7:$L$38,A15)+COUNTIFS($M$7:$M$38,A15)>0,2,1) -> 2 | R15: =IF(AND(OR(L15="",COUNTIFS($A$7:$A$38,L15,$I$7:$I$38,1)=1),OR(M15="",COUNTIFS($A$7:$A$38,M15,$I$7:$I$38,1)=1)),1,0) -> 0 | S15: =IF(AND(I15=0,R15=1,E15<>"Блокирано",E15<>"Отложено"),COUNTIFS($R$7:$R$38,1,$I$7:$I$38,0,$E$7:$E$38,"<>Блокирано",$E$7:$E$38,"<>Отложено",$K$7:$K$38,">"&K15)+COUNTIFS($R$7:R15,1,$I$7:I15,0,$E$7:E15,"<>Блокирано",$E$7:E15,"<>Отложено",$K$7:K15,K15),"") | T15: =HYPERLINK("BDS_Plan.docx#T09","T09 в Word") -> T09 в Word | U15: Всички активни сделки имат NextActionAt, StageEnteredAt, Owner и доказателство за етап.
A16: T10 | B16: 14 дни | C16: Въведи scoring и списък за звънене | D16: Sales Ops | E16: Не е започнато | F16: =Допускания!$D$6+5 -> 46291 | I16: =IF(E16="Готово",1,0) -> 0 | J16: =IF(I16=1,IF(R16=1,"Готово по отметка","Отметнато; провери условията"),IF(E16="Отложено","Отложено",IF(R16=0,"Чака зависимост",IF(E16="Блокирано","Премахни блокирането",IF(F16<Допускания!$D$7,"Просрочено","За изпълнение"))))) -> Чака зависимост | K16: =N16*O16*Q16/P16 -> 32 | L16: T05 | M16: T09 | N16: 4 | O16: 4 | P16: 1 | Q16: =IF(COUNTIFS($L$7:$L$38,A16)+COUNTIFS($M$7:$M$38,A16)>0,2,1) -> 2 | R16: =IF(AND(OR(L16="",COUNTIFS($A$7:$A$38,L16,$I$7:$I$38,1)=1),OR(M16="",COUNTIFS($A$7:$A$38,M16,$I$7:$I$38,1)=1)),1,0) -> 0 | S16: =IF(AND(I16=0,R16=1,E16<>"Блокирано",E16<>"Отложено"),COUNTIFS($R$7:$R$38,1,$I$7:$I$38,0,$E$7:$E$38,"<>Блокирано",$E$7:$E$38,"<>Отложено",$K$7:$K$38,">"&K16)+COUNTIFS($R$7:R16,1,$I$7:I16,0,$E$7:E16,"<>Блокирано",$E$7:E16,"<>Отложено",$K$7:K16,K16),"") | T16: =HYPERLINK("BDS_Plan.docx#T10","T10 в Word") -> T10 в Word | U16: 20 проверени лийда са оценени по 7 критерия; DNC и дубликати са изключени.
A17: T11 | B17: 14 дни | C17: Подготви 150 проверени prospects | D17: Sales Ops | E17: Не е започнато | F17: =Допускания!$D$6+8 -> 46294 | I17: =IF(E17="Готово",1,0) -> 0 | J17: =IF(I17=1,IF(R17=1,"Готово по отметка","Отметнато; провери условията"),IF(E17="Отложено","Отложено",IF(R17=0,"Чака зависимост",IF(E17="Блокирано","Премахни блокирането",IF(F17<Допускания!$D$7,"Просрочено","За изпълнение"))))) -> Чака зависимост | K17: =N17*O17*Q17/P17 -> 12.5 | L17: T10 | N17: 5 | O17: 5 | P17: 2 | Q17: =IF(COUNTIFS($L$7:$L$38,A17)+COUNTIFS($M$7:$M$38,A17)>0,2,1) -> 1 | R17: =IF(AND(OR(L17="",COUNTIFS($A$7:$A$38,L17,$I$7:$I$38,1)=1),OR(M17="",COUNTIFS($A$7:$A$38,M17,$I$7:$I$38,1)=1)),1,0) -> 0 | S17: =IF(AND(I17=0,R17=1,E17<>"Блокирано",E17<>"Отложено"),COUNTIFS($R$7:$R$38,1,$I$7:$I$38,0,$E$7:$E$38,"<>Блокирано",$E$7:$E$38,"<>Отложено",$K$7:$K$38,">"&K17)+COUNTIFS($R$7:R17,1,$I$7:I17,0,$E$7:E17,"<>Блокирано",$E$7:E17,"<>Отложено",$K$7:K17,K17),"") | T17: =HYPERLINK("BDS_Plan.docx#T11","T11 в Word") -> T11 в Word | U17: 150 уникални подходящи бизнеса със source, дата, контакт и конкретен проблем.
A18: T12 | B18: 14 дни | C18: Изпълни 300 опита за разговор | D18: Преслав | E18: Не е започнато | F18: =Допускания!$D$6+11 -> 46297 | I18: =IF(E18="Готово",1,0) -> 0 | J18: =IF(I18=1,IF(R18=1,"Готово по отметка","Отметнато; провери условията"),IF(E18="Отложено","Отложено",IF(R18=0,"Чака зависимост",IF(E18="Блокирано","Премахни блокирането",IF(F18<Допускания!$D$7,"Просрочено","За изпълнение"))))) -> Чака зависимост | K18: =N18*O18*Q18/P18 -> 16.666667 | L18: T10 | N18: 5 | O18: 5 | P18: 3 | Q18: =IF(COUNTIFS($L$7:$L$38,A18)+COUNTIFS($M$7:$M$38,A18)>0,2,1) -> 2 | R18: =IF(AND(OR(L18="",COUNTIFS($A$7:$A$38,L18,$I$7:$I$38,1)=1),OR(M18="",COUNTIFS($A$7:$A$38,M18,$I$7:$I$38,1)=1)),1,0) -> 0 | S18: =IF(AND(I18=0,R18=1,E18<>"Блокирано",E18<>"Отложено"),COUNTIFS($R$7:$R$38,1,$I$7:$I$38,0,$E$7:$E$38,"<>Блокирано",$E$7:$E$38,"<>Отложено",$K$7:$K$38,">"&K18)+COUNTIFS($R$7:R18,1,$I$7:I18,0,$E$7:E18,"<>Блокирано",$E$7:E18,"<>Отложено",$K$7:K18,K18),"") | T18: =HYPERLINK("BDS_Plan.docx#T12","T12 в Word") -> T12 в Word | U18: 300 реални опита са записани с outcome и следващо действие; DNC е спазен.
A19: T13 | B19: 14 дни | C19: Проведи 12 discovery срещи | D19: Преслав | E19: Не е започнато | F19: =Допускания!$D$6+12 -> 46298 | I19: =IF(E19="Готово",1,0) -> 0 | J19: =IF(I19=1,IF(R19=1,"Готово по отметка","Отметнато; провери условията"),IF(E19="Отложено","Отложено",IF(R19=0,"Чака зависимост",IF(E19="Блокирано","Премахни блокирането",IF(F19<Допускания!$D$7,"Просрочено","За изпълнение"))))) -> Чака зависимост | K19: =N19*O19*Q19/P19 -> 8.3333333 | L19: T05 | M19: T09 | N19: 5 | O19: 5 | P19: 3 | Q19: =IF(COUNTIFS($L$7:$L$38,A19)+COUNTIFS($M$7:$M$38,A19)>0,2,1) -> 1 | R19: =IF(AND(OR(L19="",COUNTIFS($A$7:$A$38,L19,$I$7:$I$38,1)=1),OR(M19="",COUNTIFS($A$7:$A$38,M19,$I$7:$I$38,1)=1)),1,0) -> 0 | S19: =IF(AND(I19=0,R19=1,E19<>"Блокирано",E19<>"Отложено"),COUNTIFS($R$7:$R$38,1,$I$7:$I$38,0,$E$7:$E$38,"<>Блокирано",$E$7:$E$38,"<>Отложено",$K$7:$K$38,">"&K19)+COUNTIFS($R$7:R19,1,$I$7:I19,0,$E$7:E19,"<>Блокирано",$E$7:E19,"<>Отложено",$K$7:K19,K19),"") | T19: =HYPERLINK("BDS_Plan.docx#T13","T13 в Word") -> T13 в Word | U19: 12 проведени срещи с проблем, стойност, бюджет, срок и decision maker.
A20: T14 | B20: 14 дни | C20: Изпрати 9 квалифицирани оферти | D20: Преслав | E20: Не е започнато | F20: =Допускания!$D$6+12 -> 46298 | I20: =IF(E20="Готово",1,0) -> 0 | J20: =IF(I20=1,IF(R20=1,"Готово по отметка","Отметнато; провери условията"),IF(E20="Отложено","Отложено",IF(R20=0,"Чака зависимост",IF(E20="Блокирано","Премахни блокирането",IF(F20<Допускания!$D$7,"Просрочено","За изпълнение"))))) -> Чака зависимост | K20: =N20*O20*Q20/P20 -> 12.5 | L20: T06 | M20: T09 | N20: 5 | O20: 5 | P20: 2 | Q20: =IF(COUNTIFS($L$7:$L$38,A20)+COUNTIFS($M$7:$M$38,A20)>0,2,1) -> 1 | R20: =IF(AND(OR(L20="",COUNTIFS($A$7:$A$38,L20,$I$7:$I$38,1)=1),OR(M20="",COUNTIFS($A$7:$A$38,M20,$I$7:$I$38,1)=1)),1,0) -> 0 | S20: =IF(AND(I20=0,R20=1,E20<>"Блокирано",E20<>"Отложено"),COUNTIFS($R$7:$R$38,1,$I$7:$I$38,0,$E$7:$E$38,"<>Блокирано",$E$7:$E$38,"<>Отложено",$K$7:$K$38,">"&K20)+COUNTIFS($R$7:R20,1,$I$7:I20,0,$E$7:E20,"<>Блокирано",$E$7:E20,"<>Отложено",$K$7:K20,K20),"") | T20: =HYPERLINK("BDS_Plan.docx#T14","T14 в Word") -> T14 в Word | U20: 9 прегледани оферти с точен scope, цена, MRR опция и next step.
A21: T15 | B21: 14 дни | C21: Потвърди първите 2 платени сделки | D21: Преслав | E21: Не е започнато | F21: =Допускания!$D$6+13 -> 46299 | I21: =IF(E21="Готово",1,0) -> 0 | J21: =IF(I21=1,IF(R21=1,"Готово по отметка","Отметнато; провери условията"),IF(E21="Отложено","Отложено",IF(R21=0,"Чака зависимост",IF(E21="Блокирано","Премахни блокирането",IF(F21<Допускания!$D$7,"Просрочено","За изпълнение"))))) -> Чака зависимост | K21: =N21*O21*Q21/P21 -> 25 | L21: T06 | M21: T09 | N21: 5 | O21: 5 | P21: 2 | Q21: =IF(COUNTIFS($L$7:$L$38,A21)+COUNTIFS($M$7:$M$38,A21)>0,2,1) -> 2 | R21: =IF(AND(OR(L21="",COUNTIFS($A$7:$A$38,L21,$I$7:$I$38,1)=1),OR(M21="",COUNTIFS($A$7:$A$38,M21,$I$7:$I$38,1)=1)),1,0) -> 0 | S21: =IF(AND(I21=0,R21=1,E21<>"Блокирано",E21<>"Отложено"),COUNTIFS($R$7:$R$38,1,$I$7:$I$38,0,$E$7:$E$38,"<>Блокирано",$E$7:$E$38,"<>Отложено",$K$7:$K$38,">"&K21)+COUNTIFS($R$7:R21,1,$I$7:I21,0,$E$7:E21,"<>Блокирано",$E$7:E21,"<>Отложено",$K$7:K21,K21),"") | T21: =HYPERLINK("BDS_Plan.docx#T15","T15 в Word") -> T15 в Word | U21: 2 приети оферти и получени аванси; сумите са сверени с плащания.
A22: T16 | B22: 14 дни | C22: Въведи onboarding checklist | D22: Operations | E22: Не е започнато | F22: =Допускания!$D$6+9 -> 46295 | I22: =IF(E22="Готово",1,0) -> 0 | J22: =IF(I22=1,IF(R22=1,"Готово по отметка","Отметнато; провери условията"),IF(E22="Отложено","Отложено",IF(R22=0,"Чака зависимост",IF(E22="Блокирано","Премахни блокирането",IF(F22<Допускания!$D$7,"Просрочено","За изпълнение"))))) -> Чака зависимост | K22: =N22*O22*Q22/P22 -> 16 | L22: T06 | M22: T09 | N22: 4 | O22: 4 | P22: 2 | Q22: =IF(COUNTIFS($L$7:$L$38,A22)+COUNTIFS($M$7:$M$38,A22)>0,2,1) -> 2 | R22: =IF(AND(OR(L22="",COUNTIFS($A$7:$A$38,L22,$I$7:$I$38,1)=1),OR(M22="",COUNTIFS($A$7:$A$38,M22,$I$7:$I$38,1)=1)),1,0) -> 0 | S22: =IF(AND(I22=0,R22=1,E22<>"Блокирано",E22<>"Отложено"),COUNTIFS($R$7:$R$38,1,$I$7:$I$38,0,$E$7:$E$38,"<>Блокирано",$E$7:$E$38,"<>Отложено",$K$7:$K$38,">"&K22)+COUNTIFS($R$7:R22,1,$I$7:I22,0,$E$7:E22,"<>Блокирано",$E$7:E22,"<>Отложено",$K$7:K22,K22),"") | T22: =HYPERLINK("BDS_Plan.docx#T16","T16 в Word") -> T16 в Word | U22: Един checklist изисква плащане, brief, материали, достъпи, owner и acceptance.
A23: T17 | B23: 14 дни | C23: Направи преглед на ден 14 | D23: Преслав | E23: Не е започнато | F23: =Допускания!$D$6+13 -> 46299 | I23: =IF(E23="Готово",1,0) -> 0 | J23: =IF(I23=1,IF(R23=1,"Готово по отметка","Отметнато; провери условията"),IF(E23="Отложено","Отложено",IF(R23=0,"Чака зависимост",IF(E23="Блокирано","Премахни блокирането",IF(F23<Допускания!$D$7,"Просрочено","За изпълнение"))))) -> Чака зависимост | K23: =N23*O23*Q23/P23 -> 25 | L23: T04 | M23: T12 | N23: 5 | O23: 5 | P23: 1 | Q23: =IF(COUNTIFS($L$7:$L$38,A23)+COUNTIFS($M$7:$M$38,A23)>0,2,1) -> 1 | R23: =IF(AND(OR(L23="",COUNTIFS($A$7:$A$38,L23,$I$7:$I$38,1)=1),OR(M23="",COUNTIFS($A$7:$A$38,M23,$I$7:$I$38,1)=1)),1,0) -> 0 | S23: =IF(AND(I23=0,R23=1,E23<>"Блокирано",E23<>"Отложено"),COUNTIFS($R$7:$R$38,1,$I$7:$I$38,0,$E$7:$E$38,"<>Блокирано",$E$7:$E$38,"<>Отложено",$K$7:$K$38,">"&K23)+COUNTIFS($R$7:R23,1,$I$7:I23,0,$E$7:E23,"<>Блокирано",$E$7:E23,"<>Отложено",$K$7:K23,K23),"") | T23: =HYPERLINK("BDS_Plan.docx#T17","T17 в Word") -> T17 в Word | U23: Има сравнение план/факт, основна загуба във funnel и един следващ експеримент.
A24: T18 | B24: 30 дни | C24: Изпълни и измери един пълен проект | D24: Delivery lead | E24: Не е започнато | F24: =Допускания!$D$6+20 -> 46306 | I24: =IF(E24="Готово",1,0) -> 0 | J24: =IF(I24=1,IF(R24=1,"Готово по отметка","Отметнато; провери условията"),IF(E24="Отложено","Отложено",IF(R24=0,"Чака зависимост",IF(E24="Блокирано","Премахни блокирането",IF(F24<Допускания!$D$7,"Просрочено","За изпълнение"))))) -> Чака зависимост | K24: =N24*O24*Q24/P24 -> 13.333333 | L24: T06 | M24: T16 | N24: 5 | O24: 4 | P24: 3 | Q24: =IF(COUNTIFS($L$7:$L$38,A24)+COUNTIFS($M$7:$M$38,A24)>0,2,1) -> 2 | R24: =IF(AND(OR(L24="",COUNTIFS($A$7:$A$38,L24,$I$7:$I$38,1)=1),OR(M24="",COUNTIFS($A$7:$A$38,M24,$I$7:$I$38,1)=1)),1,0) -> 0 | S24: =IF(AND(I24=0,R24=1,E24<>"Блокирано",E24<>"Отложено"),COUNTIFS($R$7:$R$38,1,$I$7:$I$38,0,$E$7:$E$38,"<>Блокирано",$E$7:$E$38,"<>Отложено",$K$7:$K$38,">"&K24)+COUNTIFS($R$7:R24,1,$I$7:I24,0,$E$7:E24,"<>Блокирано",$E$7:E24,"<>Отложено",$K$7:K24,K24),"") | T24: =HYPERLINK("BDS_Plan.docx#T18","T18 в Word") -> T18 в Word | U24: Приет проект, QA checklist, actual hours, gross margin и customer feedback.
A25: T19 | B25: 30 дни | C25: Продай 3 платени recurring пилота | D25: Преслав | E25: Не е започнато | F25: =Допускания!$D$6+29 -> 46315 | I25: =IF(E25="Готово",1,0) -> 0 | J25: =IF(I25=1,IF(R25=1,"Готово по отметка","Отметнато; провери условията"),IF(E25="Отложено","Отложено",IF(R25=0,"Чака зависимост",IF(E25="Блокирано","Премахни блокирането",IF(F25<Допускания!$D$7,"Просрочено","За изпълнение"))))) -> Чака зависимост | K25: =N25*O25*Q25/P25 -> 13.333333 | L25: T06 | M25: T15 | N25: 5 | O25: 4 | P25: 3 | Q25: =IF(COUNTIFS($L$7:$L$38,A25)+COUNTIFS($M$7:$M$38,A25)>0,2,1) -> 2 | R25: =IF(AND(OR(L25="",COUNTIFS($A$7:$A$38,L25,$I$7:$I$38,1)=1),OR(M25="",COUNTIFS($A$7:$A$38,M25,$I$7:$I$38,1)=1)),1,0) -> 0 | S25: =IF(AND(I25=0,R25=1,E25<>"Блокирано",E25<>"Отложено"),COUNTIFS($R$7:$R$38,1,$I$7:$I$38,0,$E$7:$E$38,"<>Блокирано",$E$7:$E$38,"<>Отложено",$K$7:$K$38,">"&K25)+COUNTIFS($R$7:R25,1,$I$7:I25,0,$E$7:E25,"<>Блокирано",$E$7:E25,"<>Отложено",$K$7:K25,K25),"") | T25: =HYPERLINK("BDS_Plan.docx#T19","T19 в Word") -> T19 в Word | U25: 3 клиента плащат за ясно ограничен Growth пакет; baseline и отчет са уговорени.
A26: T20 | B26: 30 дни | C26: Въведи седмичен operating review | D26: Operations | E26: Не е започнато | F26: =Допускания!$D$6+20 -> 46306 | I26: =IF(E26="Готово",1,0) -> 0 | J26: =IF(I26=1,IF(R26=1,"Готово по отметка","Отметнато; провери условията"),IF(E26="Отложено","Отложено",IF(R26=0,"Чака зависимост",IF(E26="Блокирано","Премахни блокирането",IF(F26<Допускания!$D$7,"Просрочено","За изпълнение"))))) -> Чака зависимост | K26: =N26*O26*Q26/P26 -> 32 | L26: T01 | M26: T09 | N26: 4 | O26: 4 | P26: 1 | Q26: =IF(COUNTIFS($L$7:$L$38,A26)+COUNTIFS($M$7:$M$38,A26)>0,2,1) -> 2 | R26: =IF(AND(OR(L26="",COUNTIFS($A$7:$A$38,L26,$I$7:$I$38,1)=1),OR(M26="",COUNTIFS($A$7:$A$38,M26,$I$7:$I$38,1)=1)),1,0) -> 0 | S26: =IF(AND(I26=0,R26=1,E26<>"Блокирано",E26<>"Отложено"),COUNTIFS($R$7:$R$38,1,$I$7:$I$38,0,$E$7:$E$38,"<>Блокирано",$E$7:$E$38,"<>Отложено",$K$7:$K$38,">"&K26)+COUNTIFS($R$7:R26,1,$I$7:I26,0,$E$7:E26,"<>Блокирано",$E$7:E26,"<>Отложено",$K$7:K26,K26),"") | T26: =HYPERLINK("BDS_Plan.docx#T20","T20 в Word") -> T20 в Word | U26: Попълнени седмични показатели и месечен P&L; 13-седмичен cash outlook се преглежда.
A27: T21 | B27: 30 дни | C27: Документирай и предай първия процес | D27: Преслав | E27: Не е започнато | F27: =Допускания!$D$6+29 -> 46315 | I27: =IF(E27="Готово",1,0) -> 0 | J27: =IF(I27=1,IF(R27=1,"Готово по отметка","Отметнато; провери условията"),IF(E27="Отложено","Отложено",IF(R27=0,"Чака зависимост",IF(E27="Блокирано","Премахни блокирането",IF(F27<Допускания!$D$7,"Просрочено","За изпълнение"))))) -> Чака зависимост | K27: =N27*O27*Q27/P27 -> 20 | L27: T18 | N27: 5 | O27: 4 | P27: 2 | Q27: =IF(COUNTIFS($L$7:$L$38,A27)+COUNTIFS($M$7:$M$38,A27)>0,2,1) -> 2 | R27: =IF(AND(OR(L27="",COUNTIFS($A$7:$A$38,L27,$I$7:$I$38,1)=1),OR(M27="",COUNTIFS($A$7:$A$38,M27,$I$7:$I$38,1)=1)),1,0) -> 0 | S27: =IF(AND(I27=0,R27=1,E27<>"Блокирано",E27<>"Отложено"),COUNTIFS($R$7:$R$38,1,$I$7:$I$38,0,$E$7:$E$38,"<>Блокирано",$E$7:$E$38,"<>Отложено",$K$7:$K$38,">"&K27)+COUNTIFS($R$7:R27,1,$I$7:I27,0,$E$7:E27,"<>Блокирано",$E$7:E27,"<>Отложено",$K$7:K27,K27),"") | T27: =HYPERLINK("BDS_Plan.docx#T21","T21 в Word") -> T21 в Word | U27: Друг човек изпълнява процеса по SOP; Преслав проверява изхода, а не всяка стъпка.
A28: T22 | B28: 30 дни | C28: Провери trigger за Sales Ops | D28: Преслав | E28: Не е започнато | F28: =Допускания!$D$6+29 -> 46315 | I28: =IF(E28="Готово",1,0) -> 0 | J28: =IF(I28=1,IF(R28=1,"Готово по отметка","Отметнато; провери условията"),IF(E28="Отложено","Отложено",IF(R28=0,"Чака зависимост",IF(E28="Блокирано","Премахни блокирането",IF(F28<Допускания!$D$7,"Просрочено","За изпълнение"))))) -> Чака зависимост | K28: =N28*O28*Q28/P28 -> 6 | L28: T20 | M28: T21 | N28: 4 | O28: 3 | P28: 2 | Q28: =IF(COUNTIFS($L$7:$L$38,A28)+COUNTIFS($M$7:$M$38,A28)>0,2,1) -> 1 | R28: =IF(AND(OR(L28="",COUNTIFS($A$7:$A$38,L28,$I$7:$I$38,1)=1),OR(M28="",COUNTIFS($A$7:$A$38,M28,$I$7:$I$38,1)=1)),1,0) -> 0 | S28: =IF(AND(I28=0,R28=1,E28<>"Блокирано",E28<>"Отложено"),COUNTIFS($R$7:$R$38,1,$I$7:$I$38,0,$E$7:$E$38,"<>Блокирано",$E$7:$E$38,"<>Отложено",$K$7:$K$38,">"&K28)+COUNTIFS($R$7:R28,1,$I$7:I28,0,$E$7:E28,"<>Блокирано",$E$7:E28,"<>Отложено",$K$7:K28,K28),"") | T28: =HYPERLINK("BDS_Plan.docx#T22","T22 в Word") -> T22 в Word | U28: Измерени admin часове, SOP, KPI и бюджет; записано решение дали hiring trigger е изпълнен.
A29: T23 | B29: 30 дни | C29: Провери delivery капацитета | D29: Delivery lead | E29: Не е започнато | F29: =Допускания!$D$6+29 -> 46315 | I29: =IF(E29="Готово",1,0) -> 0 | J29: =IF(I29=1,IF(R29=1,"Готово по отметка","Отметнато; провери условията"),IF(E29="Отложено","Отложено",IF(R29=0,"Чака зависимост",IF(E29="Блокирано","Премахни блокирането",IF(F29<Допускания!$D$7,"Просрочено","За изпълнение"))))) -> Чака зависимост | K29: =N29*O29*Q29/P29 -> 20 | L29: T18 | M29: T20 | N29: 5 | O29: 4 | P29: 2 | Q29: =IF(COUNTIFS($L$7:$L$38,A29)+COUNTIFS($M$7:$M$38,A29)>0,2,1) -> 2 | R29: =IF(AND(OR(L29="",COUNTIFS($A$7:$A$38,L29,$I$7:$I$38,1)=1),OR(M29="",COUNTIFS($A$7:$A$38,M29,$I$7:$I$38,1)=1)),1,0) -> 0 | S29: =IF(AND(I29=0,R29=1,E29<>"Блокирано",E29<>"Отложено"),COUNTIFS($R$7:$R$38,1,$I$7:$I$38,0,$E$7:$E$38,"<>Блокирано",$E$7:$E$38,"<>Отложено",$K$7:$K$38,">"&K29)+COUNTIFS($R$7:R29,1,$I$7:I29,0,$E$7:E29,"<>Блокирано",$E$7:E29,"<>Отложено",$K$7:K29,K29),"") | T29: =HYPERLINK("BDS_Plan.docx#T23","T23 в Word") -> T23 в Word | U29: Платеният backlog, наличните часове и сроковете са видими; contractor има бюджет и QA.
A30: T24 | B30: 90 дни | C30: Измери 2 renewal цикъла | D30: Customer Success | E30: Не е започнато | F30: =Допускания!$D$6+74 -> 46360 | I30: =IF(E30="Готово",1,0) -> 0 | J30: =IF(I30=1,IF(R30=1,"Готово по отметка","Отметнато; провери условията"),IF(E30="Отложено","Отложено",IF(R30=0,"Чака зависимост",IF(E30="Блокирано","Премахни блокирането",IF(F30<Допускания!$D$7,"Просрочено","За изпълнение"))))) -> Чака зависимост | K30: =N30*O30*Q30/P30 -> 13.333333 | L30: T19 | M30: T20 | N30: 5 | O30: 4 | P30: 3 | Q30: =IF(COUNTIFS($L$7:$L$38,A30)+COUNTIFS($M$7:$M$38,A30)>0,2,1) -> 2 | R30: =IF(AND(OR(L30="",COUNTIFS($A$7:$A$38,L30,$I$7:$I$38,1)=1),OR(M30="",COUNTIFS($A$7:$A$38,M30,$I$7:$I$38,1)=1)),1,0) -> 0 | S30: =IF(AND(I30=0,R30=1,E30<>"Блокирано",E30<>"Отложено"),COUNTIFS($R$7:$R$38,1,$I$7:$I$38,0,$E$7:$E$38,"<>Блокирано",$E$7:$E$38,"<>Отложено",$K$7:$K$38,">"&K30)+COUNTIFS($R$7:R30,1,$I$7:I30,0,$E$7:E30,"<>Блокирано",$E$7:E30,"<>Отложено",$K$7:K30,K30),"") | T30: =HYPERLINK("BDS_Plan.docx#T24","T24 в Word") -> T24 в Word | U30: 3 пилота са минали два цикъла; известни са retention, часове и gross margin.
A31: T25 | B31: 90 дни | C31: Въведи subscription и retention регистър | D31: Customer Success | E31: Не е започнато | F31: =Допускания!$D$6+44 -> 46330 | I31: =IF(E31="Готово",1,0) -> 0 | J31: =IF(I31=1,IF(R31=1,"Готово по отметка","Отметнато; провери условията"),IF(E31="Отложено","Отложено",IF(R31=0,"Чака зависимост",IF(E31="Блокирано","Премахни блокирането",IF(F31<Допускания!$D$7,"Просрочено","За изпълнение"))))) -> Чака зависимост | K31: =N31*O31*Q31/P31 -> 20 | L31: T19 | M31: T21 | N31: 5 | O31: 4 | P31: 2 | Q31: =IF(COUNTIFS($L$7:$L$38,A31)+COUNTIFS($M$7:$M$38,A31)>0,2,1) -> 2 | R31: =IF(AND(OR(L31="",COUNTIFS($A$7:$A$38,L31,$I$7:$I$38,1)=1),OR(M31="",COUNTIFS($A$7:$A$38,M31,$I$7:$I$38,1)=1)),1,0) -> 0 | S31: =IF(AND(I31=0,R31=1,E31<>"Блокирано",E31<>"Отложено"),COUNTIFS($R$7:$R$38,1,$I$7:$I$38,0,$E$7:$E$38,"<>Блокирано",$E$7:$E$38,"<>Отложено",$K$7:$K$38,">"&K31)+COUNTIFS($R$7:R31,1,$I$7:I31,0,$E$7:E31,"<>Блокирано",$E$7:E31,"<>Отложено",$K$7:K31,K31),"") | T31: =HYPERLINK("BDS_Plan.docx#T25","T25 в Word") -> T25 в Word | U31: Всеки абонамент има owner, цена, дата за плащане, scope, последен резултат и риск.
A32: T26 | B32: 90 дни | C32: Делегирай delivery и customer success | D32: Operations | E32: Не е започнато | F32: =Допускания!$D$6+59 -> 46345 | I32: =IF(E32="Готово",1,0) -> 0 | J32: =IF(I32=1,IF(R32=1,"Готово по отметка","Отметнато; провери условията"),IF(E32="Отложено","Отложено",IF(R32=0,"Чака зависимост",IF(E32="Блокирано","Премахни блокирането",IF(F32<Допускания!$D$7,"Просрочено","За изпълнение"))))) -> Чака зависимост | K32: =N32*O32*Q32/P32 -> 10 | L32: T21 | M32: T23 | N32: 5 | O32: 3 | P32: 3 | Q32: =IF(COUNTIFS($L$7:$L$38,A32)+COUNTIFS($M$7:$M$38,A32)>0,2,1) -> 2 | R32: =IF(AND(OR(L32="",COUNTIFS($A$7:$A$38,L32,$I$7:$I$38,1)=1),OR(M32="",COUNTIFS($A$7:$A$38,M32,$I$7:$I$38,1)=1)),1,0) -> 0 | S32: =IF(AND(I32=0,R32=1,E32<>"Блокирано",E32<>"Отложено"),COUNTIFS($R$7:$R$38,1,$I$7:$I$38,0,$E$7:$E$38,"<>Блокирано",$E$7:$E$38,"<>Отложено",$K$7:$K$38,">"&K32)+COUNTIFS($R$7:R32,1,$I$7:I32,0,$E$7:E32,"<>Блокирано",$E$7:E32,"<>Отложено",$K$7:K32,K32),"") | T32: =HYPERLINK("BDS_Plan.docx#T26","T26 в Word") -> T26 в Word | U32: Има owner и заместник за QA, onboarding, support и renewal; ескалациите са описани.
A33: T27 | B33: 90 дни | C33: Докажи повторяемост на продукта | D33: Преслав | E33: Не е започнато | F33: =Допускания!$D$6+74 -> 46360 | I33: =IF(E33="Готово",1,0) -> 0 | J33: =IF(I33=1,IF(R33=1,"Готово по отметка","Отметнато; провери условията"),IF(E33="Отложено","Отложено",IF(R33=0,"Чака зависимост",IF(E33="Блокирано","Премахни блокирането",IF(F33<Допускания!$D$7,"Просрочено","За изпълнение"))))) -> Чака зависимост | K33: =N33*O33*Q33/P33 -> 20 | L33: T18 | M33: T24 | N33: 5 | O33: 4 | P33: 2 | Q33: =IF(COUNTIFS($L$7:$L$38,A33)+COUNTIFS($M$7:$M$38,A33)>0,2,1) -> 2 | R33: =IF(AND(OR(L33="",COUNTIFS($A$7:$A$38,L33,$I$7:$I$38,1)=1),OR(M33="",COUNTIFS($A$7:$A$38,M33,$I$7:$I$38,1)=1)),1,0) -> 0 | S33: =IF(AND(I33=0,R33=1,E33<>"Блокирано",E33<>"Отложено"),COUNTIFS($R$7:$R$38,1,$I$7:$I$38,0,$E$7:$E$38,"<>Блокирано",$E$7:$E$38,"<>Отложено",$K$7:$K$38,">"&K33)+COUNTIFS($R$7:R33,1,$I$7:I33,0,$E$7:E33,"<>Блокирано",$E$7:E33,"<>Отложено",$K$7:K33,K33),"") | T33: =HYPERLINK("BDS_Plan.docx#T27","T27 в Word") -> T27 в Word | U33: Поне два delivery цикъла и два renewal цикъла са измерени; офертата покрива маржа.
A34: T28 | B34: 90 дни | C34: Тествай следващ пазар | D34: Sales lead | E34: Не е започнато | F34: =Допускания!$D$6+89 -> 46375 | I34: =IF(E34="Готово",1,0) -> 0 | J34: =IF(I34=1,IF(R34=1,"Готово по отметка","Отметнато; провери условията"),IF(E34="Отложено","Отложено",IF(R34=0,"Чака зависимост",IF(E34="Блокирано","Премахни блокирането",IF(F34<Допускания!$D$7,"Просрочено","За изпълнение"))))) -> Чака зависимост | K34: =N34*O34*Q34/P34 -> 8 | L34: T27 | M34: T23 | N34: 4 | O34: 3 | P34: 3 | Q34: =IF(COUNTIFS($L$7:$L$38,A34)+COUNTIFS($M$7:$M$38,A34)>0,2,1) -> 2 | R34: =IF(AND(OR(L34="",COUNTIFS($A$7:$A$38,L34,$I$7:$I$38,1)=1),OR(M34="",COUNTIFS($A$7:$A$38,M34,$I$7:$I$38,1)=1)),1,0) -> 0 | S34: =IF(AND(I34=0,R34=1,E34<>"Блокирано",E34<>"Отложено"),COUNTIFS($R$7:$R$38,1,$I$7:$I$38,0,$E$7:$E$38,"<>Блокирано",$E$7:$E$38,"<>Отложено",$K$7:$K$38,">"&K34)+COUNTIFS($R$7:R34,1,$I$7:I34,0,$E$7:E34,"<>Блокирано",$E$7:E34,"<>Отложено",$K$7:K34,K34),"") | T34: =HYPERLINK("BDS_Plan.docx#T28","T28 в Word") -> T28 в Word | U34: Нов регион или партньорски канал е тестван с ограничен бюджет и измерен CAC.
A35: T29 | B35: 90 дни | C35: Направи 10 дневен тест без основателя | D35: Operations | E35: Не е започнато | F35: =Допускания!$D$6+89 -> 46375 | I35: =IF(E35="Готово",1,0) -> 0 | J35: =IF(I35=1,IF(R35=1,"Готово по отметка","Отметнато; провери условията"),IF(E35="Отложено","Отложено",IF(R35=0,"Чака зависимост",IF(E35="Блокирано","Премахни блокирането",IF(F35<Допускания!$D$7,"Просрочено","За изпълнение"))))) -> Чака зависимост | K35: =N35*O35*Q35/P35 -> 13.333333 | L35: T25 | M35: T26 | N35: 5 | O35: 4 | P35: 3 | Q35: =IF(COUNTIFS($L$7:$L$38,A35)+COUNTIFS($M$7:$M$38,A35)>0,2,1) -> 2 | R35: =IF(AND(OR(L35="",COUNTIFS($A$7:$A$38,L35,$I$7:$I$38,1)=1),OR(M35="",COUNTIFS($A$7:$A$38,M35,$I$7:$I$38,1)=1)),1,0) -> 0 | S35: =IF(AND(I35=0,R35=1,E35<>"Блокирано",E35<>"Отложено"),COUNTIFS($R$7:$R$38,1,$I$7:$I$38,0,$E$7:$E$38,"<>Блокирано",$E$7:$E$38,"<>Отложено",$K$7:$K$38,">"&K35)+COUNTIFS($R$7:R35,1,$I$7:I35,0,$E$7:E35,"<>Блокирано",$E$7:E35,"<>Отложено",$K$7:K35,K35),"") | T35: =HYPERLINK("BDS_Plan.docx#T29","T29 в Word") -> T29 в Word | U35: 10 работни дни без задължително участие на Преслав във всяка продажба, доставка и инцидент.
A36: T30 | B36: След условия | C36: Потвърди устойчиви 30 000 евро | D36: Преслав | E36: Не е започнато | F36: =Допускания!$D$6+179 -> 46465 | I36: =IF(E36="Готово",1,0) -> 0 | J36: =IF(I36=1,IF(R36=1,"Готово по отметка","Отметнато; провери условията"),IF(E36="Отложено","Отложено",IF(R36=0,"Чака зависимост",IF(E36="Блокирано","Премахни блокирането",IF(F36<Допускания!$D$7,"Просрочено","За изпълнение"))))) -> Чака зависимост | K36: =N36*O36*Q36/P36 -> 25 | L36: T27 | M36: T29 | N36: 5 | O36: 5 | P36: 2 | Q36: =IF(COUNTIFS($L$7:$L$38,A36)+COUNTIFS($M$7:$M$38,A36)>0,2,1) -> 2 | R36: =IF(AND(OR(L36="",COUNTIFS($A$7:$A$38,L36,$I$7:$I$38,1)=1),OR(M36="",COUNTIFS($A$7:$A$38,M36,$I$7:$I$38,1)=1)),1,0) -> 0 | S36: =IF(AND(I36=0,R36=1,E36<>"Блокирано",E36<>"Отложено"),COUNTIFS($R$7:$R$38,1,$I$7:$I$38,0,$E$7:$E$38,"<>Блокирано",$E$7:$E$38,"<>Отложено",$K$7:$K$38,">"&K36)+COUNTIFS($R$7:R36,1,$I$7:I36,0,$E$7:E36,"<>Блокирано",$E$7:E36,"<>Отложено",$K$7:K36,K36),"") | T36: =HYPERLINK("BDS_Plan.docx#T30","T30 в Word") -> T30 в Word | U36: 3 последователни приключени месеца: приход ≥30k, MRR ≥15k, марж ≥25%, навреме ≥90%, 0 SLA backlog и автономна операция.
A37: T31 | B37: След условия | C37: Подготви капацитет за 50 000 евро | D37: Преслав | E37: Не е започнато | F37: =Допускания!$D$6+269 -> 46555 | I37: =IF(E37="Готово",1,0) -> 0 | J37: =IF(I37=1,IF(R37=1,"Готово по отметка","Отметнато; провери условията"),IF(E37="Отложено","Отложено",IF(R37=0,"Чака зависимост",IF(E37="Блокирано","Премахни блокирането",IF(F37<Допускания!$D$7,"Просрочено","За изпълнение"))))) -> Чака зависимост | K37: =N37*O37*Q37/P37 -> 8 | L37: T30 | M37: T28 | N37: 4 | O37: 3 | P37: 3 | Q37: =IF(COUNTIFS($L$7:$L$38,A37)+COUNTIFS($M$7:$M$38,A37)>0,2,1) -> 2 | R37: =IF(AND(OR(L37="",COUNTIFS($A$7:$A$38,L37,$I$7:$I$38,1)=1),OR(M37="",COUNTIFS($A$7:$A$38,M37,$I$7:$I$38,1)=1)),1,0) -> 0 | S37: =IF(AND(I37=0,R37=1,E37<>"Блокирано",E37<>"Отложено"),COUNTIFS($R$7:$R$38,1,$I$7:$I$38,0,$E$7:$E$38,"<>Блокирано",$E$7:$E$38,"<>Отложено",$K$7:$K$38,">"&K37)+COUNTIFS($R$7:R37,1,$I$7:I37,0,$E$7:E37,"<>Блокирано",$E$7:E37,"<>Отложено",$K$7:K37,K37),"") | T37: =HYPERLINK("BDS_Plan.docx#T31","T31 в Word") -> T31 в Word | U37: Планът покрива около 582 productive hours и 111 уникални recurring клиента при валидиран Growth модел.
A38: T32 | B38: След условия | C38: Потвърди устойчиви 50 000 евро | D38: Преслав | E38: Не е започнато | F38: =Допускания!$D$6+359 -> 46645 | I38: =IF(E38="Готово",1,0) -> 0 | J38: =IF(I38=1,IF(R38=1,"Готово по отметка","Отметнато; провери условията"),IF(E38="Отложено","Отложено",IF(R38=0,"Чака зависимост",IF(E38="Блокирано","Премахни блокирането",IF(F38<Допускания!$D$7,"Просрочено","За изпълнение"))))) -> Чака зависимост | K38: =N38*O38*Q38/P38 -> 10 | L38: T31 | N38: 5 | O38: 4 | P38: 2 | Q38: =IF(COUNTIFS($L$7:$L$38,A38)+COUNTIFS($M$7:$M$38,A38)>0,2,1) -> 1 | R38: =IF(AND(OR(L38="",COUNTIFS($A$7:$A$38,L38,$I$7:$I$38,1)=1),OR(M38="",COUNTIFS($A$7:$A$38,M38,$I$7:$I$38,1)=1)),1,0) -> 0 | S38: =IF(AND(I38=0,R38=1,E38<>"Блокирано",E38<>"Отложено"),COUNTIFS($R$7:$R$38,1,$I$7:$I$38,0,$E$7:$E$38,"<>Блокирано",$E$7:$E$38,"<>Отложено",$K$7:$K$38,">"&K38)+COUNTIFS($R$7:R38,1,$I$7:I38,0,$E$7:E38,"<>Блокирано",$E$7:E38,"<>Отложено",$K$7:K38,K38),"") | T38: =HYPERLINK("BDS_Plan.docx#T32","T32 в Word") -> T32 в Word | U38: 3 последователни месеца ≥50k, MRR ≥30k и същите условия за марж, качество и автономност.

Sheet Седмици
A2: Седмичен отчет
A4: Попълвай в петък. Празно = липсва данни. Въведи 0, ако стойността наистина е нула.
A6: Седмица от | B6: Verified prospects | C6: Опити за разговор | D6: Контакти | E6: SQL | F6: Проведени срещи | G6: Изпратени оферти | H6: Приети сделки | I6: Получени аванси € | J6: Delivery часа | K6: Founder часа | L6: Просрочени действия | M6: Бележка | N6: Отчетът е пълен
A7: =Допускания!$D$6-WEEKDAY(Допускания!$D$6,2)+1+0 -> 46286 | N7: =IF(COUNT(B7:L7)=11,"Да","Не") -> Не
A8: =Допускания!$D$6-WEEKDAY(Допускания!$D$6,2)+1+7 -> 46293 | N8: =IF(COUNT(B8:L8)=11,"Да","Не") -> Не
A9: =Допускания!$D$6-WEEKDAY(Допускания!$D$6,2)+1+14 -> 46300 | N9: =IF(COUNT(B9:L9)=11,"Да","Не") -> Не
A10: =Допускания!$D$6-WEEKDAY(Допускания!$D$6,2)+1+21 -> 46307 | N10: =IF(COUNT(B10:L10)=11,"Да","Не") -> Не
A11: =Допускания!$D$6-WEEKDAY(Допускания!$D$6,2)+1+28 -> 46314 | N11: =IF(COUNT(B11:L11)=11,"Да","Не") -> Не
A12: =Допускания!$D$6-WEEKDAY(Допускания!$D$6,2)+1+35 -> 46321 | N12: =IF(COUNT(B12:L12)=11,"Да","Не") -> Не
A13: =Допускания!$D$6-WEEKDAY(Допускания!$D$6,2)+1+42 -> 46328 | N13: =IF(COUNT(B13:L13)=11,"Да","Не") -> Не
A14: =Допускания!$D$6-WEEKDAY(Допускания!$D$6,2)+1+49 -> 46335 | N14: =IF(COUNT(B14:L14)=11,"Да","Не") -> Не
A15: =Допускания!$D$6-WEEKDAY(Допускания!$D$6,2)+1+56 -> 46342 | N15: =IF(COUNT(B15:L15)=11,"Да","Не") -> Не
A16: =Допускания!$D$6-WEEKDAY(Допускания!$D$6,2)+1+63 -> 46349 | N16: =IF(COUNT(B16:L16)=11,"Да","Не") -> Не
A17: =Допускания!$D$6-WEEKDAY(Допускания!$D$6,2)+1+70 -> 46356 | N17: =IF(COUNT(B17:L17)=11,"Да","Не") -> Не
A18: =Допускания!$D$6-WEEKDAY(Допускания!$D$6,2)+1+77 -> 46363 | N18: =IF(COUNT(B18:L18)=11,"Да","Не") -> Не
A19: =Допускания!$D$6-WEEKDAY(Допускания!$D$6,2)+1+84 -> 46370 | N19: =IF(COUNT(B19:L19)=11,"Да","Не") -> Не
A20: =Допускания!$D$6-WEEKDAY(Допускания!$D$6,2)+1+91 -> 46377 | N20: =IF(COUNT(B20:L20)=11,"Да","Не") -> Не
A21: =Допускания!$D$6-WEEKDAY(Допускания!$D$6,2)+1+98 -> 46384 | N21: =IF(COUNT(B21:L21)=11,"Да","Не") -> Не
A22: =Допускания!$D$6-WEEKDAY(Допускания!$D$6,2)+1+105 -> 46391 | N22: =IF(COUNT(B22:L22)=11,"Да","Не") -> Не
A23: =Допускания!$D$6-WEEKDAY(Допускания!$D$6,2)+1+112 -> 46398 | N23: =IF(COUNT(B23:L23)=11,"Да","Не") -> Не
A24: =Допускания!$D$6-WEEKDAY(Допускания!$D$6,2)+1+119 -> 46405 | N24: =IF(COUNT(B24:L24)=11,"Да","Не") -> Не
A25: =Допускания!$D$6-WEEKDAY(Допускания!$D$6,2)+1+126 -> 46412 | N25: =IF(COUNT(B25:L25)=11,"Да","Не") -> Не
A26: =Допускания!$D$6-WEEKDAY(Допускания!$D$6,2)+1+133 -> 46419 | N26: =IF(COUNT(B26:L26)=11,"Да","Не") -> Не
A27: =Допускания!$D$6-WEEKDAY(Допускания!$D$6,2)+1+140 -> 46426 | N27: =IF(COUNT(B27:L27)=11,"Да","Не") -> Не
A28: =Допускания!$D$6-WEEKDAY(Допускания!$D$6,2)+1+147 -> 46433 | N28: =IF(COUNT(B28:L28)=11,"Да","Не") -> Не
A29: =Допускания!$D$6-WEEKDAY(Допускания!$D$6,2)+1+154 -> 46440 | N29: =IF(COUNT(B29:L29)=11,"Да","Не") -> Не
A30: =Допускания!$D$6-WEEKDAY(Допускания!$D$6,2)+1+161 -> 46447 | N30: =IF(COUNT(B30:L30)=11,"Да","Не") -> Не
A31: =Допускания!$D$6-WEEKDAY(Допускания!$D$6,2)+1+168 -> 46454 | N31: =IF(COUNT(B31:L31)=11,"Да","Не") -> Не
A32: =Допускания!$D$6-WEEKDAY(Допускания!$D$6,2)+1+175 -> 46461 | N32: =IF(COUNT(B32:L32)=11,"Да","Не") -> Не
A33: =Допускания!$D$6-WEEKDAY(Допускания!$D$6,2)+1+182 -> 46468 | N33: =IF(COUNT(B33:L33)=11,"Да","Не") -> Не
A34: =Допускания!$D$6-WEEKDAY(Допускания!$D$6,2)+1+189 -> 46475 | N34: =IF(COUNT(B34:L34)=11,"Да","Не") -> Не
A35: =Допускания!$D$6-WEEKDAY(Допускания!$D$6,2)+1+196 -> 46482 | N35: =IF(COUNT(B35:L35)=11,"Да","Не") -> Не
A36: =Допускания!$D$6-WEEKDAY(Допускания!$D$6,2)+1+203 -> 46489 | N36: =IF(COUNT(B36:L36)=11,"Да","Не") -> Не
A37: =Допускания!$D$6-WEEKDAY(Допускания!$D$6,2)+1+210 -> 46496 | N37: =IF(COUNT(B37:L37)=11,"Да","Не") -> Не
A38: =Допускания!$D$6-WEEKDAY(Допускания!$D$6,2)+1+217 -> 46503 | N38: =IF(COUNT(B38:L38)=11,"Да","Не") -> Не
A39: =Допускания!$D$6-WEEKDAY(Допускания!$D$6,2)+1+224 -> 46510 | N39: =IF(COUNT(B39:L39)=11,"Да","Не") -> Не
A40: =Допускания!$D$6-WEEKDAY(Допускания!$D$6,2)+1+231 -> 46517 | N40: =IF(COUNT(B40:L40)=11,"Да","Не") -> Не
A41: =Допускания!$D$6-WEEKDAY(Допускания!$D$6,2)+1+238 -> 46524 | N41: =IF(COUNT(B41:L41)=11,"Да","Не") -> Не
A42: =Допускания!$D$6-WEEKDAY(Допускания!$D$6,2)+1+245 -> 46531 | N42: =IF(COUNT(B42:L42)=11,"Да","Не") -> Не
A43: =Допускания!$D$6-WEEKDAY(Допускания!$D$6,2)+1+252 -> 46538 | N43: =IF(COUNT(B43:L43)=11,"Да","Не") -> Не
...

Sheet Месеци
A2: Реални месечни резултати
A4: Приход = признат за периода. MRR = договорен месечен run rate. Получените плащания са отделно.
A6: Месец | B6: Еднократен приход | C6: Абонаментен приход | D6: Общ приход | E6: MRR край | F6: Преки разходи | G6: Оpex с founder pay | H6: Опер. печалба | I6: Опер. марж | J6: Плащания получени | K6: Активни recurring клиенти | L6: Доставени проекти | M6: Навреме проекти | N6: Навреме % | O6: SLA просрочени | P6: Работи без основателя | Q6: Месец приключен | R6: Покрива 30k | S6: Поредни 30k | T6: Покрива 50k | U6: Поредни 50k
A7: =EDATE(DATE(YEAR(Допускания!$D$6),MONTH(Допускания!$D$6),1),-1) -> 46235 | D7: =IF(COUNT(B7:C7)<2,"",SUM(B7:C7)) | H7: =IF(OR(NOT(ISNUMBER(D7)),COUNT(F7:G7)<2),"",D7-SUM(F7:G7)) | I7: =IF(OR(NOT(ISNUMBER(H7)),D7=0),"",H7/D7) | N7: =IF(COUNT(L7:M7)<2,"",IF(L7=0,IF(M7=0,1,""),M7/L7)) | P7: Не | Q7: Не | R7: =IF(AND(Q7="Да",EOMONTH(A7,0)<Допускания!$D$7,COUNT(B7:C7)=2,COUNT(E7:G7)=3,COUNT(L7:M7)=2,ISNUMBER(O7),L7>=M7,ISNUMBER(I7),ISNUMBER(N7)),IF(AND(D7>=30000,E7>=15000,I7>=Допускания!$D$10,N7>=Допускания!$D$11,O7=0,P7="Да"),1,0),"") | S7: =IF(NOT(ISNUMBER(R7)),"",IF(R7=1,1,0)) | T7: =IF(AND(Q7="Да",EOMONTH(A7,0)<Допускания!$D$7,COUNT(B7:C7)=2,COUNT(E7:G7)=3,COUNT(L7:M7)=2,ISNUMBER(O7),L7>=M7,ISNUMBER(I7),ISNUMBER(N7)),IF(AND(D7>=50000,E7>=30000,I7>=Допускания!$D$10,N7>=Допускания!$D$11,O7=0,P7="Да"),1,0),"") | U7: =IF(NOT(ISNUMBER(T7)),"",IF(T7=1,1,0))
A8: =EDATE(DATE(YEAR(Допускания!$D$6),MONTH(Допускания!$D$6),1),0) -> 46266 | D8: =IF(COUNT(B8:C8)<2,"",SUM(B8:C8)) | H8: =IF(OR(NOT(ISNUMBER(D8)),COUNT(F8:G8)<2),"",D8-SUM(F8:G8)) | I8: =IF(OR(NOT(ISNUMBER(H8)),D8=0),"",H8/D8) | N8: =IF(COUNT(L8:M8)<2,"",IF(L8=0,IF(M8=0,1,""),M8/L8)) | P8: Не | Q8: Не | R8: =IF(AND(Q8="Да",EOMONTH(A8,0)<Допускания!$D$7,COUNT(B8:C8)=2,COUNT(E8:G8)=3,COUNT(L8:M8)=2,ISNUMBER(O8),L8>=M8,ISNUMBER(I8),ISNUMBER(N8)),IF(AND(D8>=30000,E8>=15000,I8>=Допускания!$D$10,N8>=Допускания!$D$11,O8=0,P8="Да"),1,0),"") | S8: =IF(NOT(ISNUMBER(R8)),"",IF(R8=1,IF(ISNUMBER(S7),S7+1,1),0)) | T8: =IF(AND(Q8="Да",EOMONTH(A8,0)<Допускания!$D$7,COUNT(B8:C8)=2,COUNT(E8:G8)=3,COUNT(L8:M8)=2,ISNUMBER(O8),L8>=M8,ISNUMBER(I8),ISNUMBER(N8)),IF(AND(D8>=50000,E8>=30000,I8>=Допускания!$D$10,N8>=Допускания!$D$11,O8=0,P8="Да"),1,0),"") | U8: =IF(NOT(ISNUMBER(T8)),"",IF(T8=1,IF(ISNUMBER(U7),U7+1,1),0))
A9: =EDATE(DATE(YEAR(Допускания!$D$6),MONTH(Допускания!$D$6),1),1) -> 46296 | D9: =IF(COUNT(B9:C9)<2,"",SUM(B9:C9)) | H9: =IF(OR(NOT(ISNUMBER(D9)),COUNT(F9:G9)<2),"",D9-SUM(F9:G9)) | I9: =IF(OR(NOT(ISNUMBER(H9)),D9=0),"",H9/D9) | N9: =IF(COUNT(L9:M9)<2,"",IF(L9=0,IF(M9=0,1,""),M9/L9)) | P9: Не | Q9: Не | R9: =IF(AND(Q9="Да",EOMONTH(A9,0)<Допускания!$D$7,COUNT(B9:C9)=2,COUNT(E9:G9)=3,COUNT(L9:M9)=2,ISNUMBER(O9),L9>=M9,ISNUMBER(I9),ISNUMBER(N9)),IF(AND(D9>=30000,E9>=15000,I9>=Допускания!$D$10,N9>=Допускания!$D$11,O9=0,P9="Да"),1,0),"") | S9: =IF(NOT(ISNUMBER(R9)),"",IF(R9=1,IF(ISNUMBER(S8),S8+1,1),0)) | T9: =IF(AND(Q9="Да",EOMONTH(A9,0)<Допускания!$D$7,COUNT(B9:C9)=2,COUNT(E9:G9)=3,COUNT(L9:M9)=2,ISNUMBER(O9),L9>=M9,ISNUMBER(I9),ISNUMBER(N9)),IF(AND(D9>=50000,E9>=30000,I9>=Допускания!$D$10,N9>=Допускания!$D$11,O9=0,P9="Да"),1,0),"") | U9: =IF(NOT(ISNUMBER(T9)),"",IF(T9=1,IF(ISNUMBER(U8),U8+1,1),0))
A10: =EDATE(DATE(YEAR(Допускания!$D$6),MONTH(Допускания!$D$6),1),2) -> 46327 | D10: =IF(COUNT(B10:C10)<2,"",SUM(B10:C10)) | H10: =IF(OR(NOT(ISNUMBER(D10)),COUNT(F10:G10)<2),"",D10-SUM(F10:G10)) | I10: =IF(OR(NOT(ISNUMBER(H10)),D10=0),"",H10/D10) | N10: =IF(COUNT(L10:M10)<2,"",IF(L10=0,IF(M10=0,1,""),M10/L10)) | P10: Не | Q10: Не | R10: =IF(AND(Q10="Да",EOMONTH(A10,0)<Допускания!$D$7,COUNT(B10:C10)=2,COUNT(E10:G10)=3,COUNT(L10:M10)=2,ISNUMBER(O10),L10>=M10,ISNUMBER(I10),ISNUMBER(N10)),IF(AND(D10>=30000,E10>=15000,I10>=Допускания!$D$10,N10>=Допускания!$D$11,O10=0,P10="Да"),1,0),"") | S10: =IF(NOT(ISNUMBER(R10)),"",IF(R10=1,IF(ISNUMBER(S9),S9+1,1),0)) | T10: =IF(AND(Q10="Да",EOMONTH(A10,0)<Допускания!$D$7,COUNT(B10:C10)=2,COUNT(E10:G10)=3,COUNT(L10:M10)=2,ISNUMBER(O10),L10>=M10,ISNUMBER(I10),ISNUMBER(N10)),IF(AND(D10>=50000,E10>=30000,I10>=Допускания!$D$10,N10>=Допускания!$D$11,O10=0,P10="Да"),1,0),"") | U10: =IF(NOT(ISNUMBER(T10)),"",IF(T10=1,IF(ISNUMBER(U9),U9+1,1),0))
A11: =EDATE(DATE(YEAR(Допускания!$D$6),MONTH(Допускания!$D$6),1),3) -> 46357 | D11: =IF(COUNT(B11:C11)<2,"",SUM(B11:C11)) | H11: =IF(OR(NOT(ISNUMBER(D11)),COUNT(F11:G11)<2),"",D11-SUM(F11:G11)) | I11: =IF(OR(NOT(ISNUMBER(H11)),D11=0),"",H11/D11) | N11: =IF(COUNT(L11:M11)<2,"",IF(L11=0,IF(M11=0,1,""),M11/L11)) | P11: Не | Q11: Не | R11: =IF(AND(Q11="Да",EOMONTH(A11,0)<Допускания!$D$7,COUNT(B11:C11)=2,COUNT(E11:G11)=3,COUNT(L11:M11)=2,ISNUMBER(O11),L11>=M11,ISNUMBER(I11),ISNUMBER(N11)),IF(AND(D11>=30000,E11>=15000,I11>=Допускания!$D$10,N11>=Допускания!$D$11,O11=0,P11="Да"),1,0),"") | S11: =IF(NOT(ISNUMBER(R11)),"",IF(R11=1,IF(ISNUMBER(S10),S10+1,1),0)) | T11: =IF(AND(Q11="Да",EOMONTH(A11,0)<Допускания!$D$7,COUNT(B11:C11)=2,COUNT(E11:G11)=3,COUNT(L11:M11)=2,ISNUMBER(O11),L11>=M11,ISNUMBER(I11),ISNUMBER(N11)),IF(AND(D11>=50000,E11>=30000,I11>=Допускания!$D$10,N11>=Допускания!$D$11,O11=0,P11="Да"),1,0),"") | U11: =IF(NOT(ISNUMBER(T11)),"",IF(T11=1,IF(ISNUMBER(U10),U10+1,1),0))
A12: =EDATE(DATE(YEAR(Допускания!$D$6),MONTH(Допускания!$D$6),1),4) -> 46388 | D12: =IF(COUNT(B12:C12)<2,"",SUM(B12:C12)) | H12: =IF(OR(NOT(ISNUMBER(D12)),COUNT(F12:G12)<2),"",D12-SUM(F12:G12)) | I12: =IF(OR(NOT(ISNUMBER(H12)),D12=0),"",H12/D12) | N12: =IF(COUNT(L12:M12)<2,"",IF(L12=0,IF(M12=0,1,""),M12/L12)) | P12: Не | Q12: Не | R12: =IF(AND(Q12="Да",EOMONTH(A12,0)<Допускания!$D$7,COUNT(B12:C12)=2,COUNT(E12:G12)=3,COUNT(L12:M12)=2,ISNUMBER(O12),L12>=M12,ISNUMBER(I12),ISNUMBER(N12)),IF(AND(D12>=30000,E12>=15000,I12>=Допускания!$D$10,N12>=Допускания!$D$11,O12=0,P12="Да"),1,0),"") | S12: =IF(NOT(ISNUMBER(R12)),"",IF(R12=1,IF(ISNUMBER(S11),S11+1,1),0)) | T12: =IF(AND(Q12="Да",EOMONTH(A12,0)<Допускания!$D$7,COUNT(B12:C12)=2,COUNT(E12:G12)=3,COUNT(L12:M12)=2,ISNUMBER(O12),L12>=M12,ISNUMBER(I12),ISNUMBER(N12)),IF(AND(D12>=50000,E12>=30000,I12>=Допускания!$D$10,N12>=Допускания!$D$11,O12=0,P12="Да"),1,0),"") | U12: =IF(NOT(ISNUMBER(T12)),"",IF(T12=1,IF(ISNUMBER(U11),U11+1,1),0))
A13: =EDATE(DATE(YEAR(Допускания!$D$6),MONTH(Допускания!$D$6),1),5) -> 46419 | D13: =IF(COUNT(B13:C13)<2,"",SUM(B13:C13)) | H13: =IF(OR(NOT(ISNUMBER(D13)),COUNT(F13:G13)<2),"",D13-SUM(F13:G13)) | I13: =IF(OR(NOT(ISNUMBER(H13)),D13=0),"",H13/D13) | N13: =IF(COUNT(L13:M13)<2,"",IF(L13=0,IF(M13=0,1,""),M13/L13)) | P13: Не | Q13: Не | R13: =IF(AND(Q13="Да",EOMONTH(A13,0)<Допускания!$D$7,COUNT(B13:C13)=2,COUNT(E13:G13)=3,COUNT(L13:M13)=2,ISNUMBER(O13),L13>=M13,ISNUMBER(I13),ISNUMBER(N13)),IF(AND(D13>=30000,E13>=15000,I13>=Допускания!$D$10,N13>=Допускания!$D$11,O13=0,P13="Да"),1,0),"") | S13: =IF(NOT(ISNUMBER(R13)),"",IF(R13=1,IF(ISNUMBER(S12),S12+1,1),0)) | T13: =IF(AND(Q13="Да",EOMONTH(A13,0)<Допускания!$D$7,COUNT(B13:C13)=2,COUNT(E13:G13)=3,COUNT(L13:M13)=2,ISNUMBER(O13),L13>=M13,ISNUMBER(I13),ISNUMBER(N13)),IF(AND(D13>=50000,E13>=30000,I13>=Допускания!$D$10,N13>=Допускания!$D$11,O13=0,P13="Да"),1,0),"") | U13: =IF(NOT(ISNUMBER(T13)),"",IF(T13=1,IF(ISNUMBER(U12),U12+1,1),0))
A14: =EDATE(DATE(YEAR(Допускания!$D$6),MONTH(Допускания!$D$6),1),6) -> 46447 | D14: =IF(COUNT(B14:C14)<2,"",SUM(B14:C14)) | H14: =IF(OR(NOT(ISNUMBER(D14)),COUNT(F14:G14)<2),"",D14-SUM(F14:G14)) | I14: =IF(OR(NOT(ISNUMBER(H14)),D14=0),"",H14/D14) | N14: =IF(COUNT(L14:M14)<2,"",IF(L14=0,IF(M14=0,1,""),M14/L14)) | P14: Не | Q14: Не | R14: =IF(AND(Q14="Да",EOMONTH(A14,0)<Допускания!$D$7,COUNT(B14:C14)=2,COUNT(E14:G14)=3,COUNT(L14:M14)=2,ISNUMBER(O14),L14>=M14,ISNUMBER(I14),ISNUMBER(N14)),IF(AND(D14>=30000,E14>=15000,I14>=Допускания!$D$10,N14>=Допускания!$D$11,O14=0,P14="Да"),1,0),"") | S14: =IF(NOT(ISNUMBER(R14)),"",IF(R14=1,IF(ISNUMBER(S13),S13+1,1),0)) | T14: =IF(AND(Q14="Да",EOMONTH(A14,0)<Допускания!$D$7,COUNT(B14:C14)=2,COUNT(E14:G14)=3,COUNT(L14:M14)=2,ISNUMBER(O14),L14>=M14,ISNUMBER(I14),ISNUMBER(N14)),IF(AND(D14>=50000,E14>=30000,I14>=Допускания!$D$10,N14>=Допускания!$D$11,O14=0,P14="Да"),1,0),"") | U14: =IF(NOT(ISNUMBER(T14)),"",IF(T14=1,IF(ISNUMBER(U13),U13+1,1),0))
A15: =EDATE(DATE(YEAR(Допускания!$D$6),MONTH(Допускания!$D$6),1),7) -> 46478 | D15: =IF(COUNT(B15:C15)<2,"",SUM(B15:C15)) | H15: =IF(OR(NOT(ISNUMBER(D15)),COUNT(F15:G15)<2),"",D15-SUM(F15:G15)) | I15: =IF(OR(NOT(ISNUMBER(H15)),D15=0),"",H15/D15) | N15: =IF(COUNT(L15:M15)<2,"",IF(L15=0,IF(M15=0,1,""),M15/L15)) | P15: Не | Q15: Не | R15: =IF(AND(Q15="Да",EOMONTH(A15,0)<Допускания!$D$7,COUNT(B15:C15)=2,COUNT(E15:G15)=3,COUNT(L15:M15)=2,ISNUMBER(O15),L15>=M15,ISNUMBER(I15),ISNUMBER(N15)),IF(AND(D15>=30000,E15>=15000,I15>=Допускания!$D$10,N15>=Допускания!$D$11,O15=0,P15="Да"),1,0),"") | S15: =IF(NOT(ISNUMBER(R15)),"",IF(R15=1,IF(ISNUMBER(S14),S14+1,1),0)) | T15: =IF(AND(Q15="Да",EOMONTH(A15,0)<Допускания!$D$7,COUNT(B15:C15)=2,COUNT(E15:G15)=3,COUNT(L15:M15)=2,ISNUMBER(O15),L15>=M15,ISNUMBER(I15),ISNUMBER(N15)),IF(AND(D15>=50000,E15>=30000,I15>=Допускания!$D$10,N15>=Допускания!$D$11,O15=0,P15="Да"),1,0),"") | U15: =IF(NOT(ISNUMBER(T15)),"",IF(T15=1,IF(ISNUMBER(U14),U14+1,1),0))
A16: =EDATE(DATE(YEAR(Допускания!$D$6),MONTH(Допускания!$D$6),1),8) -> 46508 | D16: =IF(COUNT(B16:C16)<2,"",SUM(B16:C16)) | H16: =IF(OR(NOT(ISNUMBER(D16)),COUNT(F16:G16)<2),"",D16-SUM(F16:G16)) | I16: =IF(OR(NOT(ISNUMBER(H16)),D16=0),"",H16/D16) | N16: =IF(COUNT(L16:M16)<2,"",IF(L16=0,IF(M16=0,1,""),M16/L16)) | P16: Не | Q16: Не | R16: =IF(AND(Q16="Да",EOMONTH(A16,0)<Допускания!$D$7,COUNT(B16:C16)=2,COUNT(E16:G16)=3,COUNT(L16:M16)=2,ISNUMBER(O16),L16>=M16,ISNUMBER(I16),ISNUMBER(N16)),IF(AND(D16>=30000,E16>=15000,I16>=Допускания!$D$10,N16>=Допускания!$D$11,O16=0,P16="Да"),1,0),"") | S16: =IF(NOT(ISNUMBER(R16)),"",IF(R16=1,IF(ISNUMBER(S15),S15+1,1),0)) | T16: =IF(AND(Q16="Да",EOMONTH(A16,0)<Допускания!$D$7,COUNT(B16:C16)=2,COUNT(E16:G16)=3,COUNT(L16:M16)=2,ISNUMBER(O16),L16>=M16,ISNUMBER(I16),ISNUMBER(N16)),IF(AND(D16>=50000,E16>=30000,I16>=Допускания!$D$10,N16>=Допускания!$D$11,O16=0,P16="Да"),1,0),"") | U16: =IF(NOT(ISNUMBER(T16)),"",IF(T16=1,IF(ISNUMBER(U15),U15+1,1),0))
A17: =EDATE(DATE(YEAR(Допускания!$D$6),MONTH(Допускания!$D$6),1),9) -> 46539 | D17: =IF(COUNT(B17:C17)<2,"",SUM(B17:C17)) | H17: =IF(OR(NOT(ISNUMBER(D17)),COUNT(F17:G17)<2),"",D17-SUM(F17:G17)) | I17: =IF(OR(NOT(ISNUMBER(H17)),D17=0),"",H17/D17) | N17: =IF(COUNT(L17:M17)<2,"",IF(L17=0,IF(M17=0,1,""),M17/L17)) | P17: Не | Q17: Не | R17: =IF(AND(Q17="Да",EOMONTH(A17,0)<Допускания!$D$7,COUNT(B17:C17)=2,COUNT(E17:G17)=3,COUNT(L17:M17)=2,ISNUMBER(O17),L17>=M17,ISNUMBER(I17),ISNUMBER(N17)),IF(AND(D17>=30000,E17>=15000,I17>=Допускания!$D$10,N17>=Допускания!$D$11,O17=0,P17="Да"),1,0),"") | S17: =IF(NOT(ISNUMBER(R17)),"",IF(R17=1,IF(ISNUMBER(S16),S16+1,1),0)) | T17: =IF(AND(Q17="Да",EOMONTH(A17,0)<Допускания!$D$7,COUNT(B17:C17)=2,COUNT(E17:G17)=3,COUNT(L17:M17)=2,ISNUMBER(O17),L17>=M17,ISNUMBER(I17),ISNUMBER(N17)),IF(AND(D17>=50000,E17>=30000,I17>=Допускания!$D$10,N17>=Допускания!$D$11,O17=0,P17="Да"),1,0),"") | U17: =IF(NOT(ISNUMBER(T17)),"",IF(T17=1,IF(ISNUMBER(U16),U16+1,1),0))
